Workbook
Name adelanto: datos!$B$111
Name adicionales: datos!$H$111
Name apellidos: datos!$D$13
Name autoconsumo: datos!$B$55
Name BUSCA: INDEX(FOTO,MATCH(t.est!$H$3,TIPO,0))
Name c_pmat: variables!$B$12
Name c_tasas: variables!$B$13
Name cap_bat: datos!$C$98
Name catastro: datos!$B$20
Name coefper: variables!$B$11
Name comision: datos!$B$113
Name consumo1: datos!$D$36
Name consumo2: datos!$B$50
Name cp: datos!$F$17
Name crecom: variables!$B$3
Name cups: datos!$H$11
Name curva: datos!$B$36
Name descuento: datos!$D$111
Name dioxido: variables!$B$7
Name direccion: datos!$B$17
Name ecovivienda: #REF!
Name email: datos!$H$13
Name empresa: datos!$F$11
Name estructura: datos!$B$102
Name fab_inv: datos!$B$72
Name fab_mod: datos!$B$62
Name fecha: datos!$D$3
Name fin120m: variables!$B$10
Name fin12m: variables!$B$8
Name fin24m: variables!$B$9
Name FOTO: t.est!$B$3:$B$11
Name idea: #REF!
Name imagentipo: INDEX(#REF!,MATCH(datos!#REF!,#REF!,0))
Name kwhkwp: variables!$B$2
Name licencia: datos!$F$113
Name localidad: datos!$D$17
Name margen_venta: variables!$B$16
Name mobateria: variables!$B$15
Name mod_bat: datos!$B$95
Name mod_bms: datos!$B$91
Name mod_inv1: datos!$B$69
Name mod_inv2: datos!$B$76
Name mod_meter: datos!$B$87
Name mod_mod: datos!$B$59
Name mod_opt: datos!$B$83
Name nif: datos!$D$11
Name nombre: datos!$B$13
Name num_bat: datos!$D$95
Name num_bms: datos!$D$91
Name num_cee: datos!$F$111
Name num_inv1: datos!$D$69
Name num_inv2: datos!$D$76
Name num_meter: datos!$D$87
Name num_mod: datos!$D$59
Name num_opt: datos!$D$83
Name p_cee: variables!$B$14
Name p_contratada: datos!$D$34
Name p_gen: datos!$C$64
Name p_mod: datos!$C$63
Name perfil: datos!$B$11

Sheet datos
B2: Canal de Entrada | D2: Fecha (fecha)
B3: Oficina Técnica | D3: =TODAY() -> 45568
B4: Nombre del Usuario
B5: Eduardo Rivera
B7: Cliente
B8: Datos de Contacto
B10: Tipo (perfil) | D10: NIF (nif) | F10: Nombre de Empresa (empresa) | H10: CUPS (cups)
B12: Nombre (nombre) | D12: Apellidos (apellidos) | F12: Teléfono (telefono) | H12: Email
B14: Dirección de la Instalación
B16: Dirección (direccion) | D16: Localidad (localidad) | F16: Código Postal (cp) | H16: Provincia (provincia)
B19: Referencia Catastral (catatro)
B21: Incentivos / Ayudas
B23: Programa de Incentivo (programa) | D23: Empresa (tamaño)
B24: Sinayuda | D24: Pequeña
B26: Validación (sólo en caso Ecovivienda)
H27: Potencia Mínima FV (kWp)
B28: Tipo de Vivienda | D28: Superficie Construída | F28: Número de plantas | H28: =IF(B29=ecov!N5, VLOOKUP(D29,ecov!B17:D26,MATCH(F29,ecov!B17:D17,0),), IF(B29=ecov!N6, VLOOKUP(D29,ecov!E17:G26,MATCH(F29,ecov!E17:G17,0),), IF(B29=ecov!N7, VLOOKUP(D29,ecov!H17:J26,MATCH(F29,ecov!H17:J17,0),), ))) -> 4.05
B29: Adosados de 2 Fachadas | D29: 125 | F29: 1 | H29: =IF(H28<=p_gen,"CUMPLE","NO CUMPLE") -> CUMPLE
B31: Consumo
B33: Tipo de Cálculo (tipo_calculo) | D33: Potencia contratada (kW) (p_contratada)
B34: Según Curvas Tipo | D34: 4
B35: Seleccionar Curva Tipo (curva) | D35: Consumo kWh/año (consumo1)
B36: Vivienda habitada todo el año | D36: 18171
B38: Consumos Mensuales (kWh/mes)
B40: Enero | D40: Mayo | F40: Septiembre
B41: 330 | D41: 212 | F41: 283
B42: Febrero | D42: Junio | F42: Octubre
B43: 276 | D43: 408 | F43: 320
B44: Marzo | D44: Julio | F44: Noviembre
B45: 232 | D45: 454 | F45: 469
B46: Abril | D46: Agosto | F46: Diciembre
B47: 154 | D47: 311 | F47: 569
B49: Consumo Total Anual (kWh/año) | C49: =SUM(C40:C48) -> 0
B50: =B41+B43+B45+B47+D41+D43+D45+D47+F41+F43+F45+F47 -> 4018
B52: Instalación Fotovoltaica
B54: Tipo de Instalación (autoconsumo) | D54: Sitema Eléctrico (sistema) | F54: nº CUPS (sólo colectivo)
B55: Autoconsumo Individual | D55: Trifásica | F55: 1
B56: Módulos Fotovoltaicos
B58: Modelo de modulo (mod_mod) | D58: Número de módulos (num_mod)
B59: AIKO N-TYPE ABC A-MAH72MW 605W | D59: 27
...

Sheet ppto
B1: Elemento | C1: Descripción | D1: Unidad de Medida | E1: Medición | F1: Coste Unitario (€) | G1: iFV Coste Total (€) | H1: iFVBAT Coste Total (€) | I1: iBAT Coste Total (€)
B2: ="Instalación de Autoconsumo Fotovoltaico de "&p_gen&" kWp" -> Instalación de Autoconsumo Fotovoltaico de 16,335 kWp
B3: Módulo Fotovoltaico | C3: =mod_mod -> AIKO N-TYPE ABC A-MAH72MW 605W | D3: Ud de módulo | E3: =num_mod -> 27 | F3: =VLOOKUP(mod_mod,t.mod!A2:H28,8,) -> 78.65 | G3: =E3*F3 -> 2123.55 | H3: =E3*F3 -> 2123.55 | K3: =G3*($G$32/$G$16) -> 4667.2678 | L3: =IF(E3=0,0,K3/E3) -> 172.86177
B4: Grupo Inversores Tipo nº1 | C4: =mod_inv1 -> HUAWEI SUN2000 20KTL M3 | D4: Ud de inversor | E4: =num_inv1 -> 1 | F4: =VLOOKUP(mod_inv1,t.inv!A2:H261,8,) -> 1784 | G4: =E4*F4 -> 1784 | H4: =E4*F4 -> 1784 | K4: =G4*($G$32/$G$16) -> 3920.9841 | L4: =IF(E4=0,0,K4/E4) -> 3920.9841
B5: Grupo Inversores Tipo nº2 | C5: =mod_inv2 -> HUAWEI SUN2000 6KTL L1 | D5: Ud de inversor | E5: =num_inv2 -> 0 | F5: =VLOOKUP(mod_inv2,t.inv!A2:H261,8,) -> 780 | G5: =E5*F5 -> 0 | H5: =E5*F5 -> 0 | K5: =G5*($G$32/$G$16) -> 0 | L5: =IF(E5=0,0,K5/E5) -> 0
B6: Equipos de medida | C6: =mod_meter -> Medidor Monofásico DDSU | D6: Ud de medidores | E6: =num_meter -> 1 | F6: =VLOOKUP(C6,t.met!A2:F13,6,) -> 95 | G6: =E6*F6 -> 95 | H6: =E6*F6 -> 95 | K6: =G6*($G$32/$G$16) -> 208.7968 | L6: =IF(E6=0,0,K6/E6) -> 208.7968
B7: Estructura | C7: =estructura -> Coplanaria aluminio | D7: Ud de módulo | E7: =num_mod -> 27 | F7: =VLOOKUP(estructura,t.est!A3:F11,6,) -> 32 | G7: =E7*F7 -> 864 | H7: =E7*F7 -> 864 | K7: =G7*($G$32/$G$16) -> 1898.9519 | L7: =IF(E7=0,0,K7/E7) -> 70.331553
B8: Optimizadores | C8: =mod_opt -> Sin Optimizador | D8: Ud de optimizador | E8: =num_opt -> 0 | F8: =VLOOKUP(C8,t.opt!A3:H21,8,) -> 0 | G8: =E8*F8 -> 0 | H8: =E8*F8 -> 0 | K8: =G8*($G$32/$G$16) -> 0 | L8: =IF(E8=0,0,K8/E8) -> 0
B9: Cableado y Pequeño Material | C9: Cableado, Aparamenta y Pequeño Material | D9: Ud de instalación | E9: 1 | F9: =c_pmat -> 552 | G9: =E9*F9 -> 552 | H9: =E9*F9 -> 552 | K9: =G9*($G$32/$G$16) -> 1213.2193 | L9: =IF(E9=0,0,K9/E9) -> 1213.2193
B10: Montaje FV | C10: Montaje de la Instalación Fotovoltaica | D10: Ud de módulo | E10: =num_mod -> 27 | F10: =IF(num_mod=0,0,VLOOKUP(num_mod,t.mon!A3:F263,6,)/E3) -> 77.777778 | G10: =E10*F10 -> 2100 | H10: =E10*F10 -> 2100 | K10: =G10*($G$32/$G$16) -> 4615.5081 | L10: =IF(E10=0,0,K10/E10) -> 170.94475
B11: ="Instalación de Baterías de "&cap_bat&" kWh" -> Instalación de Baterías de 0 kWh
B12: BMS | C12: =mod_bms -> BMS LUNA 2000 | D12: Ud de BMS | E12: =num_bms -> 0 | F12: =VLOOKUP(C12,t.bms!A3:G22,7,) -> 735 | H12: =E12*F12 -> 0 | I12: =E12*F12 -> 0
B13: Módulos de Batería | C13: =mod_bat -> DYNESS 3,6 kW 48V | D13: Ud de módulos de Batería | E13: =num_bat -> 0 | F13: =VLOOKUP(mod_bat,t.bat!A3:G23,7,) -> 745.83 | H13: =E13*F13 -> 0 | I13: =E13*F13 -> 0
B14: Montaje Batería | C14: Montaje de la Instalación de Batería | D14: Ud de kWh | E14: =num_bms -> 0 | F14: =SUM(F12:F13)*0.15 -> 222.1245 | H14: =E14*F14*0.5 -> 0 | I14: =E14*F14 -> 0
E16: Coste Directo | G16: =SUM(G3:G14) -> 7518.55 | H16: =SUM(H3:H14) -> 7518.55 | I16: =SUM(I3:I14) -> 0
E17: Coste Indirecto | G17: =VLOOKUP(num_mod,t.coi!A2:E263,5) -> 1400 | H17: =VLOOKUP(num_mod,t.coi!A2:E263,5) -> 1400 | I17: 350
E18: Coste Total | G18: =G16+G17 -> 8918.55 | H18: =H16+H17 -> 8918.55 | I18: =I16+I17 -> 350
E20: Margen
E21: Margen bruto de Venta (%) | G21: =margen_venta -> 0.36 | H21: =margen_venta -> 0.36 | I21: =margen_venta -> 0.36
E22: Margen bruto de Venta (€) | G22: =G18*G21 -> 3210.678 | H22: =H18*H21 -> 3210.678 | I22: =I18*I21 -> 126
E23: Descuento (%) | G23: =-descuento -> 0 | H23: =-descuento -> 0 | I23: =-descuento -> 0
E24: Descuento (€) | G24: =G18*G23 -> 0 | H24: =H18*H23 -> 0 | I24: =I18*I23 -> 0
E25: Margen neto de Venta (%) | G25: =G21+G23 -> 0.36 | H25: =H21+H23 -> 0.36 | I25: =I21+I23 -> 0.36
D26: =G26/2 -> 1605.339 | E26: Margen neto de Venta (€) | G26: =G18*G25 -> 3210.678 | H26: =H18*H25 -> 3210.678 | I26: =I18*I25 -> 126
E27: Subtotal Venta (sin IVA)
E28: Subtotal Venta (sin IVA) | G28: =G18+G26 -> 12129.228 | H28: =H18+H26 -> 12129.228 | I28: =I18+I26 -> 476
E29: Otros Conceptos
E30: Certificados Energéticos | G30: =p_cee*num_cee -> 0 | H30: =p_cee*num_cee -> 0 | I30: =p_cee*num_cee -> 0
E31: Adicionales | G31: =adicionales -> 4395.5 | H31: =adicionales -> 4395.5 | I31: =adicionales -> 4395.5
E32: Total (sin IVA) | G32: =G28+G30+G31 -> 16524.728 | H32: =H28+H30+H31 -> 16524.728 | I32: =I28+I30+I31 -> 4871.5
E33: IVA (21%) | G33: =G32*0.21 -> 3470.1929 | H33: =H32*0.21 -> 3470.1929 | I33: =I32*0.21 -> 1023.015
E34: Total (con IVA) | G34: =G32+G33 -> 19994.921 | H34: =H32+H33 -> 19994.921 | I34: =I32+I33 -> 5894.515 | J34: =G34/(p_gen*1000) -> 1.2240539 | K34: €/Wp
E36: Cálculo Estimado de Tasas e ICIO
E37: Presupuesto neto | G37: =G32 -> 16524.728 | H37: =H32 -> 16524.728 | I37: =I32 -> 4871.5
E38: Gastos Generales (13%) | G38: =G40*0.13 -> 1805.2224 | H38: =H40*0.13 -> 1805.2224 | I38: =I40*0.13 -> 532.18067
E39: Beneficio Industrial (6%) | G39: =G40*0.06 -> 833.17956 | H39: =H40*0.06 -> 833.17956 | I39: =I40*0.06 -> 245.62185
E40: PEM | G40: =G37/1.19 -> 13886.326 | H40: =H37/1.19 -> 13886.326 | I40: =I37/1.19 -> 4093.6975
E41: Porcentaje Licencia, tasas + ICIO (%) | G41: 0.05 | H41: 0.05 | I41: 0.05
E42: Coste Licencia, tasas + ICIO (€) | G42: =G40*G41 -> 694.3163 | H42: =H40*H41 -> 694.3163 | I42: =I40*I41 -> 204.68487
E44: Total (con IVA y Tasas) | G44: =IF(licencia="Incluídas",G34+G42,G34) -> 19994.921 | H44: =IF(licencia="Incluídas",H34+H42,H34) -> 19994.921 | I44: =IF(licencia="Incluídas",I34+I42,I34) -> 5894.515 | J44: =G44/(p_gen*1000) -> 1.2240539 | K44: €/Wp

Sheet incentivo
B2: Cálculo del Incentivo
B3: Programa de Ayudas / Incentivo | C3: =programa -> Sinayuda
B4: Perfil de Cliente | C4: =perfil -> 0
B5: Tamaño de Empresa | C5: =IF(perfil="Particular","No Aplica (particular)",tamaño) -> Pequeña
B6: Autoconsumo | C6: =autoconsumo -> Autoconsumo Individual
B7: Potencia Instalación (Wp) | C7: =p_gen*1000 -> 16335
B8: Ecovivienda
B15: Incentivo por Paneles
B16: % de ayuda | C16: =IF(AND(programa="AAE",perfil="Empresa Pequeña",p_gen*1000<=10000),0.45, IF(AND(programa="AAE",perfil="Empresa Mediana",p_gen*1000<=10000),0.25, IF(AND(programa="AAE",perfil="Empresa Grande",p_gen*1000<=10000),0.15, IF(AND(programa="AAE",perfil="Empresa Pequeña",p_gen*1000>10000),0.35, IF(AND(programa="AAE",perfil="Empresa Mediana",p_gen*1000>10000),0.25, IF(AND(programa="AAE",perfil="Empresa Grande",p_gen*1000>10000),0.15, IF(AND(programa="Ecovivienda",datos!H29="CUMPLE"),0.8, IF(AND(programa="Ecovivienda",datos!H29="NO CUMPLE"),0.65, IF(programa="Sinayuda",0,) )))))))) -> 0 | F16: =perfil -> 0
B17: € de ayuda | C17: =IF(AND(programa="AAE",perfil="Particular",autoconsumo="Autoconsumo Individual",p_gen<=10),p_gen*600, IF(AND(programa="AAE",perfil="Particular",autoconsumo="Autoconsumo Individual",p_gen<=100),p_gen*450, IF(AND(programa="AAE",perfil="Particular",autoconsumo="Autoconsumo Individual",p_gen<=1000),p_gen*350, IF(AND(programa="AAE",perfil="Particular",autoconsumo="Autoconsumo Colectivo",p_gen<=10),p_gen*710, IF(AND(programa="AAE",perfil="Particular",autoconsumo="Autoconsumo Colectivo",p_gen<=100),p_gen*535, IF(AND(programa="AAE",perfil="Particular",autoconsumo="Autoconsumo Colectivo",p_gen<=1000),p_gen*420, )))))) -> 0
B18: Incentivo por Batería
B19: % de ayuda | C19: =IF(AND(programa="AAE",perfil="Empresa",tamaño="Pequeña"),0.65, IF(AND(programa="AAE",perfil="Empresa",tamaño="Mediana"),0.55, IF(AND(programa="AAE",perfil="Empresa",tamaño="Grande"),0.45, IF(AND(programa="Ecovivienda",datos!H29="CUMPLE"),0.8, IF(AND(programa="Ecovivienda",datos!H29="NO CUMPLE"),0.65, ))))) -> 0
B20: € de ayuda | C20: =IF(AND(programa="AAE",perfil="Particular",p_gen<=10,cap_bat<10),cap_bat*490, IF(AND(programa="AAE",perfil="Particular",p_gen<=100,cap_bat<10),cap_bat*490, IF(AND(programa="AAE",perfil="Particular",p_gen<=10,cap_bat>=10),cap_bat*350, IF(AND(programa="AAE",perfil="Particular",p_gen<=100,cap_bat>=10),cap_bat*350, )))) -> 0
B21: Incentivo por Pérgola
B22: Pérgola | C22: 0
B23: Incentivo y Presupuesto Final | C23: FV | D23: FVBAT | E23: BAT
B24: Particulares
B25: Presupuesto con IVA (€) | C25: =ppto!G44 -> 19994.921 | D25: =ppto!H44 -> 19994.921 | E25: =ppto!I44 -> 5894.515
B26: Incentivo Total (€) | C26: =C25*C16+C17+C22 -> 0 | D26: =D25*C16+C20+C17+C22 -> 0 | E26: =C19*E25+C20 -> 0
B27: Incentivo Total (%) | C27: =C26/C25 -> 0 | D27: =D26/D25 -> 0 | E27: =E26/E25 -> 0
B28: Presupuesto con IVA después de Incentivo (€) | C28: =C25-C26 -> 19994.921 | D28: =D25-D26 -> 19994.921 | E28: =E25-E26 -> 5894.515
B29: Empresas
B30: Presupuesto sin IVA (€) | C30: =ppto!G32 -> 16524.728 | D30: =ppto!H32 -> 16524.728 | E30: =ppto!I32 -> 4871.5
B31: Incentivo Total (€) | C31: =C30*C16+C17+C22 -> 0 | D31: =C30*C16+(D30-C30)*C19+C20+C17+C22 -> 0 | E31: =E25*C19+C20+C17+C22 -> 0
B32: Incentivo Total (%) | C32: =C36/C30 -> 0 | D32: =D31/D30 -> 0 | E32: =E31/E30 -> 0 | F32: revisar
B33: Presupuesto con IVA después de Incentivo (€) | C33: =C25-C31 -> 19994.921 | D33: =D30-D31 -> 16524.728 | E33: =E30-E31 -> 4871.5
B34: Cálculo
B35: Perfil | C35: =perfil -> 0 | D35: =perfil -> 0 | E35: =perfil -> 0
B36: Incentivo Total (€) | C36: =IF(perfil="Particular",incentivo!C26,incentivo!C31) -> 0 | D36: =IF(perfil="Particular",incentivo!D26,incentivo!D31) -> 0 | E36: =IF(perfil="Particular",incentivo!E26,incentivo!E31) -> 0
B37: Incentivo Total (%) | C37: =IF(perfil="Particular",incentivo!C27,incentivo!C32) -> 0 | D37: =IF(perfil="Particular",incentivo!D27,incentivo!D32) -> 0 | E37: =IF(perfil="Particular",incentivo!E27,incentivo!E32) -> 0
B38: Autoconsumo y Autosuficiencia
B39: Ratio demanda / Potencia Generador (kwh/año)/(kWp) | C39: =cálculos!P7/(p_gen*1000) -> 1.1123967
B40: Tamaño de batería (kWh) | C40: - | D40: =cap_bat -> 0
B41: Ratio (kWp/kWh) Con Bat | C41: - | D41: =(p_gen)/D40 -> #DIV/0!
B42: Coeficiente | C42: - | D42: =0.6529*D41^(-1.164) -> #DIV/0!
B43: Reducción de Demanda (%) | C43: =-0.0471*C39+0.5573 -> 0.50490612 | D43: =D41*D42+(C43-0.474) -> #DIV/0!

Sheet ppto_desglose
E2: SOLAY INGENIEROS, S.L. | H2: info@solay.es
E3: Paseo de Bollullos de la Mitación 18 | H3: www.solay.es
E4: 4110, Bollullos de la Mitación, Sevilla | H4: 954 664 252
E5: B09848912
A7: PRESUPUESTO DE VENTA
A8: =ppto!B2 -> Instalación de Autoconsumo Fotovoltaico de 16,335 kWp
C13: Datos del Presupuesto de Venta | E13: Datos del Cliente
C15: Ref:
E16: =CONCATENATE(nombre," ",apellidos,)
C17: Fecha: | E17: =telefono
C18: =fecha -> 45568 | E18: =direccion | J18: 0
E19: =CONCATENATE(cp," - ",localidad," - ",provincia) -> - -
C21: Elemento | D21: Descripción | F21: Uds. | G21: Precio Ud. | H21: Importe (€)
C22: =ppto!B2 -> Instalación de Autoconsumo Fotovoltaico de 16,335 kWp
C23: =ppto!B3 -> Módulo Fotovoltaico | D23: =ppto!C3 -> AIKO N-TYPE ABC A-MAH72MW 605W | F23: =ppto!E3 -> 27 | G23: =ppto!L3 -> 172.86177 | H23: =F23*(G23*(1-$J$18)) -> 4667.2678
C24: =ppto!B4 -> Grupo Inversores Tipo nº1 | D24: =ppto!C4 -> HUAWEI SUN2000 20KTL M3 | F24: =ppto!E4 -> 1 | G24: =ppto!L4 -> 3920.9841 | H24: =F24*(G24*(1-$J$18)) -> 3920.9841
C25: =ppto!B5 -> Grupo Inversores Tipo nº2 | D25: =ppto!C5 -> HUAWEI SUN2000 6KTL L1 | G25: =$J$18 -> 0 | H25: =F25*(G25*(1-$J$18)) -> 0
C26: =ppto!B6 -> Equipos de medida | D26: =ppto!C6 -> Medidor Monofásico DDSU | F26: =ppto!E6 -> 1 | G26: =ppto!L6 -> 208.7968 | H26: =F26*(G26*(1-$J$18)) -> 208.7968
C27: =ppto!B7 -> Estructura | D27: =ppto!C7 -> Coplanaria aluminio | F27: =ppto!E7 -> 27 | G27: =ppto!L7 -> 70.331553 | H27: =F27*(G27*(1-$J$18)) -> 1898.9519
C28: =ppto!B8 -> Optimizadores | D28: =ppto!C8 -> Sin Optimizador | G28: =$J$18 -> 0 | H28: =F28*(G28*(1-$J$18)) -> 0
C29: =ppto!B9 -> Cableado y Pequeño Material | D29: =ppto!C9 -> Cableado, Aparamenta y Pequeño Material | F29: =ppto!E9 -> 1 | G29: =ppto!L9 -> 1213.2193 | H29: =F29*(G29*(1-$J$18)) -> 1213.2193
C30: =ppto!B10 -> Montaje FV | D30: =ppto!C10 -> Montaje de la Instalación Fotovoltaica | F30: =ppto!E10 -> 27 | G30: =ppto!L10 -> 170.94475 | H30: =F30*(G30*(1-$J$18)) -> 4615.5081
C32: Servicios Adicionales Incluídos
C34: Gestión completa para el cobro de las ayudas e incentivos públicos
C35: Gestión completa para la bonificación del IBI y el cobro del mismo
C36: Legalización de la Instalación en Industria
C37: Servicio de postventa
C38: Asesoramiento Energético realizado por nuestros ingenieros, sobre tarifas eléctricsa, precios, etc
F42: Base Imponible: | H42: =SUM(H23:H38) -> 16524.728
F43: IVA (21,00 %): | H43: =H42*0.21 -> 3470.1929
F44: Total con IVA: | H44: =H42+H43 -> 19994.921
A48: SOLAY es marca registrada de SOLAY INGENIEROS, S,L. Inscrita en el Registro Mercantil de Sevilla CIF: B09.848.912

Sheet variables
A1: Parámetro | B1: Valor | C1: Nombre de Variable | F1: Valor Referencia
A2: Producción kWh/año por kWp en Sevilla | B2: =datos!D113 -> 1550 | C2: kwhkwp | F2: =1668.888 -> 1668.888
A3: Consumo Recomendado kWh/Wp | B3: =800/450 -> 1.7777778 | C3: crecom
A4: Precio de la Energía (€/kWh) | B4: 0.33 | C4: preciokwh
A5: Tasa de Interés | B5: 0.035 | C5: ti
A6: Retribución de Excedentes (€/kWh) | B6: 0.105 | C6: precioexc
A7: Emisiones de CO2 (kg/kWh) | B7: 0.256 | C7: dioxido
A8: Coeficiente Financiación 12 meses | B8: 0.088972 | C8: fin12m
A9: Coeficiente Financiación 24 meses | B9: 0.046236 | C9: fin24m
A10: Coeficiente Financiación 120 meses | B10: 0.012362 | C10: fin120m
A11: Coeficiente de pérdida de producción | B11: 0.99243 | C11: coefper
A12: Coste Pequeño Material (€) | B12: =120+16*num_mod -> 552 | C12: c_pmat
A13: Coste Tasas y Licencias (€) | B13: =0.025*(ppto!G18+ppto!G26)*1.21 -> 366.90915 | C13: c_tasas
A14: Precio de Venta de CEE (€) | B14: 65 | C14: p_cee
A15: Coste Mano de Obra Batería | B15: 150 | C15: mobateria
A16: Margen de Venta | B16: =VLOOKUP(num_mod,t.mar!A1:C263,3) -> 0.36 | C16: margen_venta
A19: tabla_financiación
A20: Entidad Financiera
A21: BANCO SANTANDER

Sheet Comercial
B1: Comercial:
B2: Margen del Comercial: | C2: 0.02
C5: iFV Coste Total (€) | D5: iFVBAT Coste Total (€) | E5: iBAT Coste Total (€)
B6: Precio sin IVA | C6: =ppto!G32 -> 16524.728 | D6: =ppto!H32 -> 16524.728 | E6: =ppto!I32 -> 4871.5
B10: Margen Neto de Venta | C10: =ppto!G26 -> 3210.678
B11: Margen del Comercial | C11: =C6*C2 -> 330.49456
B12: Margen Final Solay | C12: =C10-C11 -> 2880.1834

Sheet TABLA HUAWEI
A1: Módulo | C1: LONGI LR5-72HPH 550 (HiMO5 New) 550 Wp | E1: HUAWEI - ECOVIVIENDA
A2: Potencia (Wp) | C2: =VLOOKUP(C1,t.mod!A2:H28,7,) -> 550 | E2: Tarifa 2023.10
A5: UD | B5: Potencia Paneles (kW) | C5: Modelo Inversor | D5: Modelo Panel | E5: Medidor | F5: Estructura | G5: Coste Paneles (€) | H5: Coste Inversor (€) | I5: Coste Medida (€) | J5: Coste Estructura (€) | K5: Coste Cableado (€) | L5: Coste de Montaje (€) | M5: Coste directo (€) | N5: Coste indirecto (€) | O5: Coste total (€) | P5: Margen (€) | Q5: CEEs | R5: IVA (€) | S5: Precio con IVA (€)
A7: 3 | B7: =A7*$C$2/1000 -> 1.65 | C7: HUAWEI SUN2000 2KTL L1 | D7: =$C$1 -> LONGI LR5-72HPH 550 (HiMO5 New) 550 Wp | E7: Medidor Monofásico DDSU | F7: Coplanaria aluminio | G7: =VLOOKUP($C$1,t.mod!$A$2:$H$28,8,)*A7 -> 280.5 | H7: =VLOOKUP(C7,t.inv!$A$2:$H$261,8,) -> 462 | I7: =VLOOKUP(E7,t.met!$A$2:$F$13,6,) -> 95 | J7: =VLOOKUP(F7,t.est!$A$3:$F$11,6,)*A7 -> 96 | K7: =120+16*A7 -> 168 | L7: =VLOOKUP(A7,t.mon!$A$3:$F$263,6,) -> 850 | M7: =SUM(G7:L7) -> 1951.5 | N7: =VLOOKUP(A7,t.coi!$A$2:$E$263,5) -> 700 | O7: =M7+N7 -> 2651.5 | P7: =VLOOKUP(A7,t.mar!$A$1:$C$263,3)*O7 -> 1060.6 | Q7: =p_cee*2 -> 130 | R7: =(O7+P7+Q7)*0.21 -> 806.841 | S7: =O7+P7+Q7+R7 -> 4648.941
A8: 4 | B8: =A8*$C$2/1000 -> 2.2 | C8: HUAWEI SUN2000 2KTL L1 | D8: =$C$1 -> LONGI LR5-72HPH 550 (HiMO5 New) 550 Wp | E8: Medidor Monofásico DDSU | F8: Coplanaria aluminio | G8: =VLOOKUP($C$1,t.mod!$A$2:$H$28,8,)*A8 -> 374 | H8: =VLOOKUP(C8,t.inv!$A$2:$H$261,8,) -> 462 | I8: =VLOOKUP(E8,t.met!$A$2:$F$13,6,) -> 95 | J8: =VLOOKUP(F8,t.est!$A$3:$F$11,6,)*A8 -> 128 | K8: =120+16*A8 -> 184 | L8: =VLOOKUP(A8,t.mon!$A$3:$F$263,6,) -> 850 | M8: =SUM(G8:L8) -> 2093 | N8: =VLOOKUP(A8,t.coi!$A$2:$E$263,5) -> 700 | O8: =M8+N8 -> 2793 | P8: =VLOOKUP(A8,t.mar!$A$1:$C$263,3)*O8 -> 1117.2 | Q8: =p_cee*2 -> 130 | R8: =(O8+P8+Q8)*0.21 -> 848.442 | S8: =O8+P8+Q8+R8 -> 4888.642
A9: 5 | B9: =A9*$C$2/1000 -> 2.75 | C9: HUAWEI SUN2000 3KTL L1 | D9: =$C$1 -> LONGI LR5-72HPH 550 (HiMO5 New) 550 Wp | E9: Medidor Monofásico DDSU | F9: Coplanaria aluminio | G9: =VLOOKUP($C$1,t.mod!$A$2:$H$28,8,)*A9 -> 467.5 | H9: =VLOOKUP(C9,t.inv!$A$2:$H$261,8,) -> 545.05 | I9: =VLOOKUP(E9,t.met!$A$2:$F$13,6,) -> 95 | J9: =VLOOKUP(F9,t.est!$A$3:$F$11,6,)*A9 -> 160 | K9: =120+16*A9 -> 200 | L9: =VLOOKUP(A9,t.mon!$A$3:$F$263,6,) -> 900 | M9: =SUM(G9:L9) -> 2367.55 | N9: =VLOOKUP(A9,t.coi!$A$2:$E$263,5) -> 800 | O9: =M9+N9 -> 3167.55 | P9: =VLOOKUP(A9,t.mar!$A$1:$C$263,3)*O9 -> 1235.3445 | Q9: =p_cee*2 -> 130 | R9: =(O9+P9+Q9)*0.21 -> 951.90785 | S9: =O9+P9+Q9+R9 -> 5484.8023
A10: 6 | B10: =A10*$C$2/1000 -> 3.3 | C10: HUAWEI SUN2000 3KTL L1 | D10: =$C$1 -> LONGI LR5-72HPH 550 (HiMO5 New) 550 Wp | E10: Medidor Monofásico DDSU | F10: Coplanaria aluminio | G10: =VLOOKUP($C$1,t.mod!$A$2:$H$28,8,)*A10 -> 561 | H10: =VLOOKUP(C10,t.inv!$A$2:$H$261,8,) -> 545.05 | I10: =VLOOKUP(E10,t.met!$A$2:$F$13,6,) -> 95 | J10: =VLOOKUP(F10,t.est!$A$3:$F$11,6,)*A10 -> 192 | K10: =120+16*A10 -> 216 | L10: =VLOOKUP(A10,t.mon!$A$3:$F$263,6,) -> 1050 | M10: =SUM(G10:L10) -> 2659.05 | N10: =VLOOKUP(A10,t.coi!$A$2:$E$263,5) -> 800 | O10: =M10+N10 -> 3459.05 | P10: =VLOOKUP(A10,t.mar!$A$1:$C$263,3)*O10 -> 1349.0295 | Q10: =p_cee*2 -> 130 | R10: =(O10+P10+Q10)*0.21 -> 1036.9967 | S10: =O10+P10+Q10+R10 -> 5975.0762
A11: 7 | B11: =A11*$C$2/1000 -> 3.85 | C11: HUAWEI SUN2000 4KTL L1 | D11: =$C$1 -> LONGI LR5-72HPH 550 (HiMO5 New) 550 Wp | E11: Medidor Monofásico DDSU | F11: Coplanaria aluminio | G11: =VLOOKUP($C$1,t.mod!$A$2:$H$28,8,)*A11 -> 654.5 | H11: =VLOOKUP(C11,t.inv!$A$2:$H$261,8,) -> 664.95 | I11: =VLOOKUP(E11,t.met!$A$2:$F$13,6,) -> 95 | J11: =VLOOKUP(F11,t.est!$A$3:$F$11,6,)*A11 -> 224 | K11: =120+16*A11 -> 232 | L11: =VLOOKUP(A11,t.mon!$A$3:$F$263,6,) -> 1250 | M11: =SUM(G11:L11) -> 3120.45 | N11: =VLOOKUP(A11,t.coi!$A$2:$E$263,5) -> 850 | O11: =M11+N11 -> 3970.45 | P11: =VLOOKUP(A11,t.mar!$A$1:$C$263,3)*O11 -> 1508.771 | Q11: =p_cee*2 -> 130 | R11: =(O11+P11+Q11)*0.21 -> 1177.9364 | S11: =O11+P11+Q11+R11 -> 6787.1574
A12: 8 | B12: =A12*$C$2/1000 -> 4.4 | C12: HUAWEI SUN2000 4KTL L1 | D12: =$C$1 -> LONGI LR5-72HPH 550 (HiMO5 New) 550 Wp | E12: Medidor Monofásico DDSU | F12: Coplanaria aluminio | G12: =VLOOKUP($C$1,t.mod!$A$2:$H$28,8,)*A12 -> 748 | H12: =VLOOKUP(C12,t.inv!$A$2:$H$261,8,) -> 664.95 | I12: =VLOOKUP(E12,t.met!$A$2:$F$13,6,) -> 95 | J12: =VLOOKUP(F12,t.est!$A$3:$F$11,6,)*A12 -> 256 | K12: =120+16*A12 -> 248 | L12: =VLOOKUP(A12,t.mon!$A$3:$F$263,6,) -> 1250 | M12: =SUM(G12:L12) -> 3261.95 | N12: =VLOOKUP(A12,t.coi!$A$2:$E$263,5) -> 850 | O12: =M12+N12 -> 4111.95 | P12: =VLOOKUP(A12,t.mar!$A$1:$C$263,3)*O12 -> 1562.541 | Q12: =p_cee*2 -> 130 | R12: =(O12+P12+Q12)*0.21 -> 1218.9431 | S12: =O12+P12+Q12+R12 -> 7023.4341
A13: 9 | B13: =A13*$C$2/1000 -> 4.95 | C13: HUAWEI SUN2000 5KTL L1 | D13: =$C$1 -> LONGI LR5-72HPH 550 (HiMO5 New) 550 Wp | E13: Medidor Monofásico DDSU | F13: Coplanaria aluminio | G13: =VLOOKUP($C$1,t.mod!$A$2:$H$28,8,)*A13 -> 841.5 | H13: =VLOOKUP(C13,t.inv!$A$2:$H$261,8,) -> 722.7 | I13: =VLOOKUP(E13,t.met!$A$2:$F$13,6,) -> 95 | J13: =VLOOKUP(F13,t.est!$A$3:$F$11,6,)*A13 -> 288 | K13: =120+16*A13 -> 264 | L13: =VLOOKUP(A13,t.mon!$A$3:$F$263,6,) -> 1350 | M13: =SUM(G13:L13) -> 3561.2 | N13: =VLOOKUP(A13,t.coi!$A$2:$E$263,5) -> 900 | O13: =M13+N13 -> 4461.2 | P13: =VLOOKUP(A13,t.mar!$A$1:$C$263,3)*O13 -> 1650.644 | Q13: =p_cee*2 -> 130 | R13: =(O13+P13+Q13)*0.21 -> 1310.7872 | S13: =O13+P13+Q13+R13 -> 7552.6312
A14: 10 | B14: =A14*$C$2/1000 -> 5.5 | C14: HUAWEI SUN2000 5KTL L1 | D14: =$C$1 -> LONGI LR5-72HPH 550 (HiMO5 New) 550 Wp | E14: Medidor Monofásico DDSU | F14: Coplanaria aluminio | G14: =VLOOKUP($C$1,t.mod!$A$2:$H$28,8,)*A14 -> 935 | H14: =VLOOKUP(C14,t.inv!$A$2:$H$261,8,) -> 722.7 | I14: =VLOOKUP(E14,t.met!$A$2:$F$13,6,) -> 95 | J14: =VLOOKUP(F14,t.est!$A$3:$F$11,6,)*A14 -> 320 | K14: =120+16*A14 -> 280 | L14: =VLOOKUP(A14,t.mon!$A$3:$F$263,6,) -> 1400 | M14: =SUM(G14:L14) -> 3752.7 | N14: =VLOOKUP(A14,t.coi!$A$2:$E$263,5) -> 950 | O14: =M14+N14 -> 4702.7 | P14: =VLOOKUP(A14,t.mar!$A$1:$C$263,3)*O14 -> 1739.999 | Q14: =p_cee*2 -> 130 | R14: =(O14+P14+Q14)*0.21 -> 1380.2668 | S14: =O14+P14+Q14+R14 -> 7952.9658
A15: 11 | B15: =A15*$C$2/1000 -> 6.05 | C15: HUAWEI SUN2000 6KTL L1 | D15: =$C$1 -> LONGI LR5-72HPH 550 (HiMO5 New) 550 Wp | E15: Medidor Monofásico DDSU | F15: Coplanaria aluminio | G15: =VLOOKUP($C$1,t.mod!$A$2:$H$28,8,)*A15 -> 1028.5 | H15: =VLOOKUP(C15,t.inv!$A$2:$H$261,8,) -> 780 | I15: =VLOOKUP(E15,t.met!$A$2:$F$13,6,) -> 95 | J15: =VLOOKUP(F15,t.est!$A$3:$F$11,6,)*A15 -> 352 | K15: =120+16*A15 -> 296 | L15: =VLOOKUP(A15,t.mon!$A$3:$F$263,6,) -> 1400 | M15: =SUM(G15:L15) -> 3951.5 | N15: =VLOOKUP(A15,t.coi!$A$2:$E$263,5) -> 950 | O15: =M15+N15 -> 4901.5 | P15: =VLOOKUP(A15,t.mar!$A$1:$C$263,3)*O15 -> 1813.555 | Q15: =p_cee*2 -> 130 | R15: =(O15+P15+Q15)*0.21 -> 1437.4615 | S15: =O15+P15+Q15+R15 -> 8282.5166
A16: 12 | B16: =A16*$C$2/1000 -> 6.6 | C16: HUAWEI SUN2000 6KTL L1 | D16: =$C$1 -> LONGI LR5-72HPH 550 (HiMO5 New) 550 Wp | E16: Medidor Monofásico DDSU | F16: Coplanaria aluminio | G16: =VLOOKUP($C$1,t.mod!$A$2:$H$28,8,)*A16 -> 1122 | H16: =VLOOKUP(C16,t.inv!$A$2:$H$261,8,) -> 780 | I16: =VLOOKUP(E16,t.met!$A$2:$F$13,6,) -> 95 | J16: =VLOOKUP(F16,t.est!$A$3:$F$11,6,)*A16 -> 384 | K16: =120+16*A16 -> 312 | L16: =VLOOKUP(A16,t.mon!$A$3:$F$263,6,) -> 1450 | M16: =SUM(G16:L16) -> 4143 | N16: =VLOOKUP(A16,t.coi!$A$2:$E$263,5) -> 1000 | O16: =M16+N16 -> 5143 | P16: =VLOOKUP(A16,t.mar!$A$1:$C$263,3)*O16 -> 1902.91 | Q16: =p_cee*2 -> 130 | R16: =(O16+P16+Q16)*0.21 -> 1506.9411 | S16: =O16+P16+Q16+R16 -> 8682.8511
A17: 13 | B17: =A17*$C$2/1000 -> 7.15 | C17: HUAWEI SUN2000 6KTL L1 | D17: =$C$1 -> LONGI LR5-72HPH 550 (HiMO5 New) 550 Wp | E17: Medidor Monofásico DDSU | F17: Coplanaria aluminio | G17: =VLOOKUP($C$1,t.mod!$A$2:$H$28,8,)*A17 -> 1215.5 | H17: =VLOOKUP(C17,t.inv!$A$2:$H$261,8,) -> 780 | I17: =VLOOKUP(E17,t.met!$A$2:$F$13,6,) -> 95 | J17: =VLOOKUP(F17,t.est!$A$3:$F$11,6,)*A17 -> 416 | K17: =120+16*A17 -> 328 | L17: =VLOOKUP(A17,t.mon!$A$3:$F$263,6,) -> 1450 | M17: =SUM(G17:L17) -> 4284.5 | N17: =VLOOKUP(A17,t.coi!$A$2:$E$263,5) -> 1000 | O17: =M17+N17 -> 5284.5 | P17: =VLOOKUP(A17,t.mar!$A$1:$C$263,3)*O17 -> 1955.265 | Q17: =p_cee*2 -> 130 | R17: =(O17+P17+Q17)*0.21 -> 1547.6506 | S17: =O17+P17+Q17+R17 -> 8917.4156
A18: 14 | B18: =A18*$C$2/1000 -> 7.7 | C18: HUAWEI SUN2000 6KTL L1 | D18: =$C$1 -> LONGI LR5-72HPH 550 (HiMO5 New) 550 Wp | E18: Medidor Monofásico DDSU | F18: Coplanaria aluminio | G18: =VLOOKUP($C$1,t.mod!$A$2:$H$28,8,)*A18 -> 1309 | H18: =VLOOKUP(C18,t.inv!$A$2:$H$261,8,) -> 780 | I18: =VLOOKUP(E18,t.met!$A$2:$F$13,6,) -> 95 | J18: =VLOOKUP(F18,t.est!$A$3:$F$11,6,)*A18 -> 448 | K18: =120+16*A18 -> 344 | L18: =VLOOKUP(A18,t.mon!$A$3:$F$263,6,) -> 1500 | M18: =SUM(G18:L18) -> 4476 | N18: =VLOOKUP(A18,t.coi!$A$2:$E$263,5) -> 1100 | O18: =M18+N18 -> 5576 | P18: =VLOOKUP(A18,t.mar!$A$1:$C$263,3)*O18 -> 2063.12 | Q18: =p_cee*2 -> 130 | R18: =(O18+P18+Q18)*0.21 -> 1631.5152 | S18: =O18+P18+Q18+R18 -> 9400.6352
... A42: 26 | B42: =A42*$C$2/1000 -> 14.3 | C42: HUAWEI SUN2000 15KTL M2 | D42: =$C$1 -> LONGI LR5-72HPH 550 (HiMO5 New) 550 Wp | E42: Medidor Trifásico DTSU | F42: Coplanaria aluminio | G42: =VLOOKUP($C$1,t.mod!$A$2:$H$28,8,)*A42 -> 2431 | H42: =VLOOKUP(C42,t.inv!$A$2:$H$261,8,) -> 1669 | I42: =VLOOKUP(E42,t.met!$A$2:$F$13,6,) -> 135 | J42: =VLOOKUP(F42,t.est!$A$3:$F$11,6,)*A42 -> 832 | K42: =120+16*A42 -> 536 | L42: =VLOOKUP(A42,t.mon!$A$3:$F$263,6,) -> 2000 | M42: =SUM(G42:L42) -> 7603 | N42: =VLOOKUP(A42,t.coi!$A$2:$E$263,5) -> 1400 | O42: =M42+N42 -> 9003 | P42: =VLOOKUP(A42,t.mar!$A$1:$C$263,3)*O42 -> 3241.08 | Q42: =p_cee*2 -> 130 | R42: =(O42+P42+Q42)*0.21 -> 2598.5568 | S42: =O42+P42+Q42+R42 -> 14972.637
A44: Precios con todo incluído, salvo coste de Tasas/ICIO de Licencia de Obra.

Sheet TABLA ENPHASE
A1: Módulo | C1: LONGI LR5-72HPH 550 (HiMO5 New) 550 Wp | E1: MICROINVERSORES - ECOVIVIENDA
A2: Potencia (Wp) | C2: =VLOOKUP(C1,t.mod!A2:H28,7,) -> 550 | E2: Tarifa 2023.11
A5: UD | B5: Potencia Paneles (kW) | C5: Modelo Inversor | D5: Modelo Panel | E5: Medidor | F5: Estructura | G5: Coste Paneles (€) | H5: Coste Inversor (€) | I5: Coste Medida (€) | J5: Coste Estructura (€) | K5: Coste Cableado (€) | L5: Coste de Montaje (€) | M5: Coste directo (€) | N5: Coste indirecto (€) | O5: Coste total (€) | P5: Margen (€) | Q5: CEEs | R5: IVA (€) | S5: Precio con IVA (€)
A7: 3 | B7: =A7*$C$2/1000 -> 1.65 | C7: IQ8HC-72-M-INT | D7: =$C$1 -> LONGI LR5-72HPH 550 (HiMO5 New) 550 Wp | E7: Enphase Envoy-S Mono/Tri - Metered | F7: Coplanaria aluminio | G7: =VLOOKUP($C$1,t.mod!$A$2:$H$28,8,)*A7 -> 280.5 | H7: =VLOOKUP(C7,t.inv!$A$2:$H$261,8,)*A7 -> 395.55 | I7: =VLOOKUP(E7,t.met!$A$2:$F$13,6,) -> 301.63 | J7: =VLOOKUP(F7,t.est!$A$3:$F$11,6,)*A7 -> 96 | K7: =120+16*A7 -> 168 | L7: =VLOOKUP(A7,t.mon!$A$3:$F$263,6,) -> 850 | M7: =SUM(G7:L7) -> 2091.68 | N7: =VLOOKUP(A7,t.coi!$A$2:$E$263,5) -> 700 | O7: =M7+N7 -> 2791.68 | P7: =VLOOKUP(A7,t.mar!$A$1:$C$263,3)*O7 -> 1116.672 | Q7: =p_cee*2 -> 130 | R7: =(O7+P7+Q7)*0.21 -> 848.05392 | S7: =O7+P7+Q7+R7 -> 4886.4059
A8: 4 | B8: =A8*$C$2/1000 -> 2.2 | C8: IQ8HC-72-M-INT | D8: =$C$1 -> LONGI LR5-72HPH 550 (HiMO5 New) 550 Wp | E8: Enphase Envoy-S Mono/Tri - Metered | F8: Coplanaria aluminio | G8: =VLOOKUP($C$1,t.mod!$A$2:$H$28,8,)*A8 -> 374 | H8: =VLOOKUP(C8,t.inv!$A$2:$H$261,8,)*A8 -> 527.4 | I8: =VLOOKUP(E8,t.met!$A$2:$F$13,6,) -> 301.63 | J8: =VLOOKUP(F8,t.est!$A$3:$F$11,6,)*A8 -> 128 | K8: =120+16*A8 -> 184 | L8: =VLOOKUP(A8,t.mon!$A$3:$F$263,6,) -> 850 | M8: =SUM(G8:L8) -> 2365.03 | N8: =VLOOKUP(A8,t.coi!$A$2:$E$263,5) -> 700 | O8: =M8+N8 -> 3065.03 | P8: =VLOOKUP(A8,t.mar!$A$1:$C$263,3)*O8 -> 1226.012 | Q8: =p_cee*2 -> 130 | R8: =(O8+P8+Q8)*0.21 -> 928.41882 | S8: =O8+P8+Q8+R8 -> 5349.4608
A9: 5 | B9: =A9*$C$2/1000 -> 2.75 | C9: IQ8HC-72-M-INT | D9: =$C$1 -> LONGI LR5-72HPH 550 (HiMO5 New) 550 Wp | E9: Enphase Envoy-S Mono/Tri - Metered | F9: Coplanaria aluminio | G9: =VLOOKUP($C$1,t.mod!$A$2:$H$28,8,)*A9 -> 467.5 | H9: =VLOOKUP(C9,t.inv!$A$2:$H$261,8,)*A9 -> 659.25 | I9: =VLOOKUP(E9,t.met!$A$2:$F$13,6,) -> 301.63 | J9: =VLOOKUP(F9,t.est!$A$3:$F$11,6,)*A9 -> 160 | K9: =120+16*A9 -> 200 | L9: =VLOOKUP(A9,t.mon!$A$3:$F$263,6,) -> 900 | M9: =SUM(G9:L9) -> 2688.38 | N9: =VLOOKUP(A9,t.coi!$A$2:$E$263,5) -> 800 | O9: =M9+N9 -> 3488.38 | P9: =VLOOKUP(A9,t.mar!$A$1:$C$263,3)*O9 -> 1360.4682 | Q9: =p_cee*2 -> 130 | R9: =(O9+P9+Q9)*0.21 -> 1045.5581 | S9: =O9+P9+Q9+R9 -> 6024.4063
A10: 6 | B10: =A10*$C$2/1000 -> 3.3 | C10: IQ8HC-72-M-INT | D10: =$C$1 -> LONGI LR5-72HPH 550 (HiMO5 New) 550 Wp | E10: Enphase Envoy-S Mono/Tri - Metered | F10: Coplanaria aluminio | G10: =VLOOKUP($C$1,t.mod!$A$2:$H$28,8,)*A10 -> 561 | H10: =VLOOKUP(C10,t.inv!$A$2:$H$261,8,)*A10 -> 791.1 | I10: =VLOOKUP(E10,t.met!$A$2:$F$13,6,) -> 301.63 | J10: =VLOOKUP(F10,t.est!$A$3:$F$11,6,)*A10 -> 192 | K10: =120+16*A10 -> 216 | L10: =VLOOKUP(A10,t.mon!$A$3:$F$263,6,) -> 1050 | M10: =SUM(G10:L10) -> 3111.73 | N10: =VLOOKUP(A10,t.coi!$A$2:$E$263,5) -> 800 | O10: =M10+N10 -> 3911.73 | P10: =VLOOKUP(A10,t.mar!$A$1:$C$263,3)*O10 -> 1525.5747 | Q10: =p_cee*2 -> 130 | R10: =(O10+P10+Q10)*0.21 -> 1169.134 | S10: =O10+P10+Q10+R10 -> 6736.4387
A11: 7 | B11: =A11*$C$2/1000 -> 3.85 | C11: IQ8HC-72-M-INT | D11: =$C$1 -> LONGI LR5-72HPH 550 (HiMO5 New) 550 Wp | E11: Enphase Envoy-S Mono/Tri - Metered | F11: Coplanaria aluminio | G11: =VLOOKUP($C$1,t.mod!$A$2:$H$28,8,)*A11 -> 654.5 | H11: =VLOOKUP(C11,t.inv!$A$2:$H$261,8,)*A11 -> 922.95 | I11: =VLOOKUP(E11,t.met!$A$2:$F$13,6,) -> 301.63 | J11: =VLOOKUP(F11,t.est!$A$3:$F$11,6,)*A11 -> 224 | K11: =120+16*A11 -> 232 | L11: =VLOOKUP(A11,t.mon!$A$3:$F$263,6,) -> 1250 | M11: =SUM(G11:L11) -> 3585.08 | N11: =VLOOKUP(A11,t.coi!$A$2:$E$263,5) -> 850 | O11: =M11+N11 -> 4435.08 | P11: =VLOOKUP(A11,t.mar!$A$1:$C$263,3)*O11 -> 1685.3304 | Q11: =p_cee*2 -> 130 | R11: =(O11+P11+Q11)*0.21 -> 1312.5862 | S11: =O11+P11+Q11+R11 -> 7562.9966
A12: 8 | B12: =A12*$C$2/1000 -> 4.4 | C12: IQ8HC-72-M-INT | D12: =$C$1 -> LONGI LR5-72HPH 550 (HiMO5 New) 550 Wp | E12: Enphase Envoy-S Mono/Tri - Metered | F12: Coplanaria aluminio | G12: =VLOOKUP($C$1,t.mod!$A$2:$H$28,8,)*A12 -> 748 | H12: =VLOOKUP(C12,t.inv!$A$2:$H$261,8,)*A12 -> 1054.8 | I12: =VLOOKUP(E12,t.met!$A$2:$F$13,6,) -> 301.63 | J12: =VLOOKUP(F12,t.est!$A$3:$F$11,6,)*A12 -> 256 | K12: =120+16*A12 -> 248 | L12: =VLOOKUP(A12,t.mon!$A$3:$F$263,6,) -> 1250 | M12: =SUM(G12:L12) -> 3858.43 | N12: =VLOOKUP(A12,t.coi!$A$2:$E$263,5) -> 850 | O12: =M12+N12 -> 4708.43 | P12: =VLOOKUP(A12,t.mar!$A$1:$C$263,3)*O12 -> 1789.2034 | Q12: =p_cee*2 -> 130 | R12: =(O12+P12+Q12)*0.21 -> 1391.803 | S12: =O12+P12+Q12+R12 -> 8019.4364
A13: 9 | B13: =A13*$C$2/1000 -> 4.95 | C13: IQ8HC-72-M-INT | D13: =$C$1 -> LONGI LR5-72HPH 550 (HiMO5 New) 550 Wp | E13: Enphase Envoy-S Mono/Tri - Metered | F13: Coplanaria aluminio | G13: =VLOOKUP($C$1,t.mod!$A$2:$H$28,8,)*A13 -> 841.5 | H13: =VLOOKUP(C13,t.inv!$A$2:$H$261,8,)*A13 -> 1186.65 | I13: =VLOOKUP(E13,t.met!$A$2:$F$13,6,) -> 301.63 | J13: =VLOOKUP(F13,t.est!$A$3:$F$11,6,)*A13 -> 288 | K13: =120+16*A13 -> 264 | L13: =VLOOKUP(A13,t.mon!$A$3:$F$263,6,) -> 1350 | M13: =SUM(G13:L13) -> 4231.78 | N13: =VLOOKUP(A13,t.coi!$A$2:$E$263,5) -> 900 | O13: =M13+N13 -> 5131.78 | P13: =VLOOKUP(A13,t.mar!$A$1:$C$263,3)*O13 -> 1898.7586 | Q13: =p_cee*2 -> 130 | R13: =(O13+P13+Q13)*0.21 -> 1503.7131 | S13: =O13+P13+Q13+R13 -> 8664.2517
A14: 10 | B14: =A14*$C$2/1000 -> 5.5 | C14: IQ8HC-72-M-INT | D14: =$C$1 -> LONGI LR5-72HPH 550 (HiMO5 New) 550 Wp | E14: Enphase Envoy-S Mono/Tri - Metered | F14: Coplanaria aluminio | G14: =VLOOKUP($C$1,t.mod!$A$2:$H$28,8,)*A14 -> 935 | H14: =VLOOKUP(C14,t.inv!$A$2:$H$261,8,)*A14 -> 1318.5 | I14: =VLOOKUP(E14,t.met!$A$2:$F$13,6,) -> 301.63 | J14: =VLOOKUP(F14,t.est!$A$3:$F$11,6,)*A14 -> 320 | K14: =120+16*A14 -> 280 | L14: =VLOOKUP(A14,t.mon!$A$3:$F$263,6,) -> 1400 | M14: =SUM(G14:L14) -> 4555.13 | N14: =VLOOKUP(A14,t.coi!$A$2:$E$263,5) -> 950 | O14: =M14+N14 -> 5505.13 | P14: =VLOOKUP(A14,t.mar!$A$1:$C$263,3)*O14 -> 2036.8981 | Q14: =p_cee*2 -> 130 | R14: =(O14+P14+Q14)*0.21 -> 1611.1259 | S14: =O14+P14+Q14+R14 -> 9283.154
A15: 11 | B15: =A15*$C$2/1000 -> 6.05 | C15: IQ8HC-72-M-INT | D15: =$C$1 -> LONGI LR5-72HPH 550 (HiMO5 New) 550 Wp | E15: Enphase Envoy-S Mono/Tri - Metered | F15: Coplanaria aluminio | G15: =VLOOKUP($C$1,t.mod!$A$2:$H$28,8,)*A15 -> 1028.5 | H15: =VLOOKUP(C15,t.inv!$A$2:$H$261,8,)*A15 -> 1450.35 | I15: =VLOOKUP(E15,t.met!$A$2:$F$13,6,) -> 301.63 | J15: =VLOOKUP(F15,t.est!$A$3:$F$11,6,)*A15 -> 352 | K15: =120+16*A15 -> 296 | L15: =VLOOKUP(A15,t.mon!$A$3:$F$263,6,) -> 1400 | M15: =SUM(G15:L15) -> 4828.48 | N15: =VLOOKUP(A15,t.coi!$A$2:$E$263,5) -> 950 | O15: =M15+N15 -> 5778.48 | P15: =VLOOKUP(A15,t.mar!$A$1:$C$263,3)*O15 -> 2138.0376 | Q15: =p_cee*2 -> 130 | R15: =(O15+P15+Q15)*0.21 -> 1689.7687 | S15: =O15+P15+Q15+R15 -> 9736.2863
A16: 12 | B16: =A16*$C$2/1000 -> 6.6 | C16: IQ8HC-72-M-INT | D16: =$C$1 -> LONGI LR5-72HPH 550 (HiMO5 New) 550 Wp | E16: Enphase Envoy-S Mono/Tri - Metered | F16: Coplanaria aluminio | G16: =VLOOKUP($C$1,t.mod!$A$2:$H$28,8,)*A16 -> 1122 | H16: =VLOOKUP(C16,t.inv!$A$2:$H$261,8,)*A16 -> 1582.2 | I16: =VLOOKUP(E16,t.met!$A$2:$F$13,6,) -> 301.63 | J16: =VLOOKUP(F16,t.est!$A$3:$F$11,6,)*A16 -> 384 | K16: =120+16*A16 -> 312 | L16: =VLOOKUP(A16,t.mon!$A$3:$F$263,6,) -> 1450 | M16: =SUM(G16:L16) -> 5151.83 | N16: =VLOOKUP(A16,t.coi!$A$2:$E$263,5) -> 1000 | O16: =M16+N16 -> 6151.83 | P16: =VLOOKUP(A16,t.mar!$A$1:$C$263,3)*O16 -> 2276.1771 | Q16: =p_cee*2 -> 130 | R16: =(O16+P16+Q16)*0.21 -> 1797.1815 | S16: =O16+P16+Q16+R16 -> 10355.189
A17: 13 | B17: =A17*$C$2/1000 -> 7.15 | C17: IQ8HC-72-M-INT | D17: =$C$1 -> LONGI LR5-72HPH 550 (HiMO5 New) 550 Wp | E17: Enphase Envoy-S Mono/Tri - Metered | F17: Coplanaria aluminio | G17: =VLOOKUP($C$1,t.mod!$A$2:$H$28,8,)*A17 -> 1215.5 | H17: =VLOOKUP(C17,t.inv!$A$2:$H$261,8,)*A17 -> 1714.05 | I17: =VLOOKUP(E17,t.met!$A$2:$F$13,6,) -> 301.63 | J17: =VLOOKUP(F17,t.est!$A$3:$F$11,6,)*A17 -> 416 | K17: =120+16*A17 -> 328 | L17: =VLOOKUP(A17,t.mon!$A$3:$F$263,6,) -> 1450 | M17: =SUM(G17:L17) -> 5425.18 | N17: =VLOOKUP(A17,t.coi!$A$2:$E$263,5) -> 1000 | O17: =M17+N17 -> 6425.18 | P17: =VLOOKUP(A17,t.mar!$A$1:$C$263,3)*O17 -> 2377.3166 | Q17: =p_cee*2 -> 130 | R17: =(O17+P17+Q17)*0.21 -> 1875.8243 | S17: =O17+P17+Q17+R17 -> 10808.321
A18: 14 | B18: =A18*$C$2/1000 -> 7.7 | C18: IQ8HC-72-M-INT | D18: =$C$1 -> LONGI LR5-72HPH 550 (HiMO5 New) 550 Wp | E18: Enphase Envoy-S Mono/Tri - Metered | F18: Coplanaria aluminio | G18: =VLOOKUP($C$1,t.mod!$A$2:$H$28,8,)*A18 -> 1309 | H18: =VLOOKUP(C18,t.inv!$A$2:$H$261,8,)*A18 -> 1845.9 | I18: =VLOOKUP(E18,t.met!$A$2:$F$13,6,) -> 301.63 | J18: =VLOOKUP(F18,t.est!$A$3:$F$11,6,)*A18 -> 448 | K18: =120+16*A18 -> 344 | L18: =VLOOKUP(A18,t.mon!$A$3:$F$263,6,) -> 1500 | M18: =SUM(G18:L18) -> 5748.53 | N18: =VLOOKUP(A18,t.coi!$A$2:$E$263,5) -> 1100 | O18: =M18+N18 -> 6848.53 | P18: =VLOOKUP(A18,t.mar!$A$1:$C$263,3)*O18 -> 2533.9561 | Q18: =p_cee*2 -> 130 | R18: =(O18+P18+Q18)*0.21 -> 1997.6221 | S18: =O18+P18+Q18+R18 -> 11510.108
... A42: 26 | B42: =A42*$C$2/1000 -> 14.3 | C42: IQ8HC-72-M-INT | D42: =$C$1 -> LONGI LR5-72HPH 550 (HiMO5 New) 550 Wp | E42: Enphase Envoy-S Mono/Tri - Metered | F42: Coplanaria aluminio | G42: =VLOOKUP($C$1,t.mod!$A$2:$H$28,8,)*A42 -> 2431 | H42: =VLOOKUP(C42,t.inv!$A$2:$H$261,8,)*A42 -> 3428.1 | I42: =VLOOKUP(E42,t.met!$A$2:$F$13,6,) -> 301.63 | J42: =VLOOKUP(F42,t.est!$A$3:$F$11,6,)*A42 -> 832 | K42: =120+16*A42 -> 536 | L42: =VLOOKUP(A42,t.mon!$A$3:$F$263,6,) -> 2000 | M42: =SUM(G42:L42) -> 9528.73 | N42: =VLOOKUP(A42,t.coi!$A$2:$E$263,5) -> 1400 | O42: =M42+N42 -> 10928.73 | P42: =VLOOKUP(A42,t.mar!$A$1:$C$263,3)*O42 -> 3934.3428 | Q42: =p_cee*2 -> 130 | R42: =(O42+P42+Q42)*0.21 -> 3148.5453 | S42: =O42+P42+Q42+R42 -> 18141.618
A44: Precios con todo incluído, salvo coste de Tasas/ICIO de Licencia de Obra.

Sheet cálculos
B5: Situación Actual
B6: Mes | C6: Enero | D6: Febrero | E6: Marzo | F6: Abril | G6: Mayo | H6: Junio | I6: Julio | J6: Agosto | K6: Septiembre | L6: Octubre | M6: Noviembre | N6: Diciembre | P6: Total
B7: Demanda Mensual (kWh/mes) | C7: =t.con!C3 -> 2180.52 | D7: =t.con!D3 -> 1998.81 | E7: =t.con!E3 -> 1090.26 | F7: =t.con!F3 -> 1090.26 | G7: =t.con!G3 -> 1271.97 | H7: =t.con!H3 -> 1271.97 | I7: =t.con!I3 -> 1635.39 | J7: =t.con!J3 -> 1817.1 | ... N7: =t.con!N3 -> 2180.52 | P7: =SUM(C7:N7) -> 18171
B8: Gasto Mensual (€/mes) | C8: =C7*preciokwh -> 719.5716 | D8: =D7*preciokwh -> 659.6073 | E8: =E7*preciokwh -> 359.7858 | F8: =F7*preciokwh -> 359.7858 | G8: =G7*preciokwh -> 419.7501 | H8: =H7*preciokwh -> 419.7501 | I8: =I7*preciokwh -> 539.6787 | J8: =J7*preciokwh -> 599.643 | ... N8: =N7*preciokwh -> 719.5716 | P8: =SUM(C8:N8) -> 5996.43
B9: Emisiones de CO2 (kg/mes) | C9: =C7*dioxido -> 558.21312 | D9: =D7*dioxido -> 511.69536 | E9: =E7*dioxido -> 279.10656 | F9: =F7*dioxido -> 279.10656 | G9: =G7*dioxido -> 325.62432 | H9: =H7*dioxido -> 325.62432 | I9: =I7*dioxido -> 418.65984 | J9: =J7*dioxido -> 465.1776 | ... N9: =N7*dioxido -> 558.21312 | P9: =SUM(C9:N9) -> 4651.776
B10: Producción FV
B11: Mes | C11: Enero | D11: Febrero | E11: Marzo | F11: Abril | G11: Mayo | H11: Junio | I11: Julio | J11: Agosto | K11: Septiembre | L11: Octubre | M11: Noviembre | N11: Diciembre | P11: Total
B12: Referencia PVGIS 0º Azoimut y 35º Inclinación | C12: 118.59 | D12: 118.19 | E12: 140.32 | F12: 142.16 | G12: 155.06 | H12: 153.95 | I12: 163.58 | J12: 161.53 | K12: 144.55 | L12: 132.32 | M12: 112.65 | N12: 113.4 | P12: =SUM(C12:N12) -> 1656.3
B13: Coeficiente Mensual | C13: =C12/$P$12 -> 0.071599348 | D13: =D12/$P$12 -> 0.071357846 | E13: =E12/$P$12 -> 0.084718952 | F13: =F12/$P$12 -> 0.085829862 | G13: =G12/$P$12 -> 0.093618306 | H13: =H12/$P$12 -> 0.092948137 | I13: =I12/$P$12 -> 0.098762302 | J13: =J12/$P$12 -> 0.097524603 | ... N13: =N12/$P$12 -> 0.068465858 | P13: =SUM(C13:N13) -> 1
B14: Producción FV (kWh/mes) | C14: =$P$14*C13 -> 1812.8418 | D14: =$P$14*D13 -> 1806.7271 | E14: =$P$14*E13 -> 2145.0203 | F14: =$P$14*F13 -> 2173.1477 | G14: =$P$14*G13 -> 2370.3453 | H14: =$P$14*H13 -> 2353.3771 | I14: =$P$14*I13 -> 2500.5874 | J14: =$P$14*J13 -> 2469.2498 | ... N14: =$P$14*N13 -> 1733.5042 | P14: =p_gen*kwhkwp -> 25319.25
B16: Cálculo de Reducción media de la demanda | C16: Sin Baterías
B17: Mes | C17: Enero | D17: Febrero | E17: Marzo | F17: Abril | G17: Mayo | H17: Junio | I17: Julio | J17: Agosto | K17: Septiembre | L17: Octubre | M17: Noviembre | N17: Diciembre | P17: Total
B18: Cálculo de Reducción media de demanda (%) | C18: =incentivo!C43 -> 0.50490612 | D18: =incentivo!C43 -> 0.50490612 | E18: =incentivo!C43 -> 0.50490612 | F18: =incentivo!C43 -> 0.50490612 | G18: =incentivo!C43 -> 0.50490612 | H18: =incentivo!C43 -> 0.50490612 | I18: =incentivo!C43 -> 0.50490612 | J18: =incentivo!C43 -> 0.50490612 | K18: =incentivo!C43 -> 0.50490612 | L18: =incentivo!C43 -> 0.50490612 | M18: =incentivo!C43 -> 0.50490612 | N18: =incentivo!C43 -> 0.50490612
B19: Incremento de Producción respecto a producción media (kWh) | C19: =C14-$P$14/12 -> -297.09571 | D19: =D14-$P$14/12 -> -303.21036 | E19: =E14-$P$14/12 -> 35.082822 | F19: =F14-$P$14/12 -> 63.210227 | G19: =G14-$P$14/12 -> 260.40779 | H19: =H14-$P$14/12 -> 243.43963 | I19: =I14-$P$14/12 -> 390.6499 | J19: =J14-$P$14/12 -> 359.31231 | ... N19: =N14-$P$14/12 -> -376.43333 | P19: =SUM(C19:N19) -> -2.5011104e-12
B20: Incremento de Demanda respecto a demanda media (kWh) | C20: =C7-$P$7/12 -> 666.27 | D20: =D7-$P$7/12 -> 484.56 | E20: =E7-$P$7/12 -> -423.99 | F20: =F7-$P$7/12 -> -423.99 | G20: =G7-$P$7/12 -> -242.28 | H20: =H7-$P$7/12 -> -242.28 | I20: =I7-$P$7/12 -> 121.14 | J20: =J7-$P$7/12 -> 302.85 | ... N20: =N7-$P$7/12 -> 666.27 | P20: =SUM(C20:N20) -> 0
B21: Incremento Porcentual de Producción respecto media (%) | C21: =C19/$P$14 -> -0.011733985 | D21: =D19/$P$14 -> -0.011975488 | E21: =E19/$P$14 -> 0.0013856185 | F21: =F19/$P$14 -> 0.0024965284 | G21: =G19/$P$14 -> 0.010284973 | H21: =H19/$P$14 -> 0.0096148041 | I21: =I19/$P$14 -> 0.015428968 | J21: =J19/$P$14 -> 0.01419127 | ... N21: =N19/$P$14 -> -0.014867476 | P21: =SUM(C21:N21) -> -9.7144515e-17
B22: Incremento Porcentual de Demanda respecto media (%) | C22: =C20/$P$7 -> 0.036666667 | D22: =D20/$P$7 -> 0.026666667 | E22: =E20/$P$7 -> -0.023333333 | F22: =F20/$P$7 -> -0.023333333 | G22: =G20/$P$7 -> -0.013333333 | H22: =H20/$P$7 -> -0.013333333 | I22: =I20/$P$7 -> 0.0066666667 | J22: =J20/$P$7 -> 0.016666667 | ... N22: =N20/$P$7 -> 0.036666667 | P22: =SUM(C22:N22) -> 0
B23: Autoconsumo, Reducción de la Demanda Corregida (%) | C23: =C18+C21-C22 -> 0.45650546 | D23: =D18+D21-D22 -> 0.46626396 | E23: =E18+E21-E22 -> 0.52962507 | F23: =F18+F21-F22 -> 0.53073598 | G23: =G18+G21-G22 -> 0.52852442 | H23: =H18+H21-H22 -> 0.52785425 | I23: =I18+I21-I22 -> 0.51366842 | J23: =J18+J21-J22 -> 0.50243072 | ... N23: =N18+N21-N22 -> 0.45337197 | P23: =SUM(C23:N23)/12 -> 0.50490612
B25: Autoconsumo y Autosuficiencia | C25: Sin Baterías
B26: Mes | C26: Enero | D26: Febrero | E26: Marzo | F26: Abril | G26: Mayo | H26: Junio | I26: Julio | J26: Agosto | K26: Septiembre | L26: Octubre | M26: Noviembre | N26: Diciembre | P26: Total
B27: Autoconsumo, Reducción de la Demanda (kWh/mes) | C27: =C7*C23 -> 995.41929 | D27: =D7*D23 -> 931.97307 | E27: =E7*E23 -> 577.42903 | F27: =F7*F23 -> 578.64021 | G27: =G7*G23 -> 672.26721 | H27: =H7*H23 -> 671.41477 | I27: =I7*I23 -> 840.04819 | J27: =J7*J23 -> 912.96686 | ... N27: =N7*N23 -> 988.58666 | P27: =SUM(C27:N27) -> 9037.6685
B28: Demanda mensual (kWh/mes) | C28: =C7-C27 -> 1185.1007 | D28: =D7-D27 -> 1066.8369 | E28: =E7-E27 -> 512.83097 | F28: =F7-F27 -> 511.61979 | G28: =G7-G27 -> 599.70279 | H28: =H7-H27 -> 600.55523 | I28: =I7-I27 -> 795.34181 | J28: =J7-J27 -> 904.13314 | ... N28: =N7-N27 -> 1191.9333 | P28: =SUM(C28:N28) -> 9133.3315
B29: Excedentes (kWh/mes) | C29: =C14-(C7-C28) -> 817.4225 | D29: =D14-(D7-D28) -> 874.75407 | E29: =E14-E27 -> 1567.5913 | F29: =F14-F27 -> 1594.5075 | G29: =G14-G27 -> 1698.0781 | H29: =H14-H27 -> 1681.9624 | I29: =I14-I27 -> 1660.5392 | J29: =J14-J27 -> 1556.2829 | K29: =K14-K27 -> 1629.4694 | L29: =L14-L27 -> 1450.5642 | ... N29: =N14-N27 -> 744.91751 | P29: =SUM(C29:N29) -> 16281.582 | R29: =C7-C28 -> 995.41929
B30: Gasto | C30: Sin Baterías
B31: Mes | C31: Enero | D31: Febrero | E31: Marzo | F31: Abril | G31: Mayo | H31: Junio | I31: Julio | J31: Agosto | K31: Septiembre | L31: Octubre | M31: Noviembre | N31: Diciembre | P31: Total
B32: Gasto mensual (€/mes) | C32: =C28*preciokwh -> 391.08323 | D32: =D28*preciokwh -> 352.05619 | E32: =E28*preciokwh -> 169.23422 | F32: =F28*preciokwh -> 168.83453 | G32: =G28*preciokwh -> 197.90192 | H32: =H28*preciokwh -> 198.18322 | I32: =I28*preciokwh -> 262.4628 | J32: =J28*preciokwh -> 298.36394 | ... N32: =N28*preciokwh -> 393.338 | P32: =SUM(C32:N32) -> 3013.9994
B33: Ahorro mensual (€/mes) | C33: =C27*preciokwh+C29*precioexc -> 414.31773 | D33: =D27*preciokwh+D29*precioexc -> 399.40029 | E33: =E27*preciokwh+E29*precioexc -> 355.14866 | F33: =F27*preciokwh+F29*precioexc -> 358.37456 | G33: =G27*preciokwh+G29*precioexc -> 400.14638 | H33: =H27*preciokwh+H29*precioexc -> 398.17292 | I33: =I27*preciokwh+I29*precioexc -> 451.57252 | J33: =J27*preciokwh+J29*precioexc -> 464.68877 | ... N33: =N27*preciokwh+N29*precioexc -> 404.44993 | P33: =SUM(C33:N33) -> 4691.9967
B34: Emisiones | C34: Sin Baterías
B35: Mes | C35: Enero | D35: Febrero | E35: Marzo | F35: Abril | G35: Mayo | H35: Junio | I35: Julio | J35: Agosto | K35: Septiembre | L35: Octubre | M35: Noviembre | N35: Diciembre | P35: Total
B36: Emisiones de CO2 (kg/mes) | C36: =C28*dioxido -> 303.38578 | D36: =D28*dioxido -> 273.11025 | E36: =E28*dioxido -> 131.28473 | F36: =F28*dioxido -> 130.97467 | G36: =G28*dioxido -> 153.52391 | H36: =H28*dioxido -> 153.74214 | I36: =I28*dioxido -> 203.6075 | J36: =J28*dioxido -> 231.45808 | ... N36: =N28*dioxido -> 305.13494 | P36: =SUM(C36:N36) -> 2338.1329
B38: Cálculo de Reducción media de la demanda | C38: Con Baterías
B39: Mes | C39: Enero | D39: Febrero | E39: Marzo | F39: Abril | G39: Mayo | H39: Junio | I39: Julio | J39: Agosto | K39: Septiembre | L39: Octubre | M39: Noviembre | N39: Diciembre | P39: Total
B40: Cálculo de Reducción media de demanda (%) | C40: =incentivo!D43 -> #DIV/0! | D40: =incentivo!D43 -> #DIV/0! | E40: =incentivo!D43 -> #DIV/0! | F40: =incentivo!D43 -> #DIV/0! | G40: =incentivo!D43 -> #DIV/0! | H40: =incentivo!D43 -> #DIV/0! | I40: =incentivo!D43 -> #DIV/0! | J40: =incentivo!D43 -> #DIV/0! | K40: =incentivo!D43 -> #DIV/0! | L40: =incentivo!D43 -> #DIV/0! | M40: =incentivo!D43 -> #DIV/0! | N40: =incentivo!D43 -> #DIV/0!
B41: Incremento de Producción respecto a producción media (kWh) | C41: =C19 -> -297.09571 | D41: =D19 -> -303.21036 | E41: =E19 -> 35.082822 | F41: =F19 -> 63.210227 | G41: =G19 -> 260.40779 | H41: =H19 -> 243.43963 | I41: =I19 -> 390.6499 | J41: =J19 -> 359.31231 | ... N41: =N19 -> -376.43333 | P41: =SUM(C41:N41) -> -2.5011104e-12
B42: Incremento de Demanda respecto a demanda media (kWh) | C42: =C20 -> 666.27 | D42: =D20 -> 484.56 | E42: =E20 -> -423.99 | F42: =F20 -> -423.99 | G42: =G20 -> -242.28 | H42: =H20 -> -242.28 | I42: =I20 -> 121.14 | J42: =J20 -> 302.85 | ... N42: =N20 -> 666.27 | P42: =SUM(C42:N42) -> 0
B43: Incremento Porcentual de Producción respecto media (%) | C43: =C21 -> -0.011733985 | D43: =D21 -> -0.011975488 | E43: =E21 -> 0.0013856185 | F43: =F21 -> 0.0024965284 | G43: =G21 -> 0.010284973 | H43: =H21 -> 0.0096148041 | I43: =I21 -> 0.015428968 | J43: =J21 -> 0.01419127 | ... N43: =N21 -> -0.014867476 | P43: =SUM(C43:N43) -> -9.7144515e-17
B44: Incremento Porcentual de Demanda respecto media (%) | C44: =C22 -> 0.036666667 | D44: =D22 -> 0.026666667 | E44: =E22 -> -0.023333333 | F44: =F22 -> -0.023333333 | G44: =G22 -> -0.013333333 | H44: =H22 -> -0.013333333 | I44: =I22 -> 0.0066666667 | J44: =J22 -> 0.016666667 | ... N44: =N22 -> 0.036666667 | P44: =SUM(C44:N44) -> 0
B45: Autoconsumo, Reducción de la Demanda Corregida (%) | C45: =C40+C43-C44 -> #DIV/0! | D45: =D40+D43-D44 -> #DIV/0! | E45: =E40+E43-E44 -> #DIV/0! | F45: =F40+F43-F44 -> #DIV/0! | G45: =G40+G43-G44 -> #DIV/0! | H45: =H40+H43-H44 -> #DIV/0! | I45: =I40+I43-I44 -> #DIV/0! | J45: =J40+J43-J44 -> #DIV/0! | ... N45: =N40+N43-N44 -> #DIV/0! | P45: =SUM(C45:N45)/12 -> #DIV/0!
B47: Autoconsumo y Autosuficiencia | C47: Con Baterías
B48: Mes | C48: Enero | D48: Febrero | E48: Marzo | F48: Abril | G48: Mayo | H48: Junio | I48: Julio | J48: Agosto | K48: Septiembre | L48: Octubre | M48: Noviembre | N48: Diciembre | P48: Total
...

Sheet finan
C2: Financiación | D2: Sin Bateria | E2: Con Batería | F2: Sólo Batería
C3: Presupuesto total, con IVA (€) | D3: =ppto!G44 -> 19994.921 | E3: =ppto!H44 -> 19994.921 | F3: =ppto!I44 -> 5894.515
C4: Financiación a 12 meses | D4: =D3*fin12m -> 1778.9881 | E4: =E3*fin12m -> 1778.9881 | F4: =F3*fin12m -> 524.44679
C5: Financiación a 24 meses | D5: =D3*fin24m -> 924.48516 | E5: =E3*fin24m -> 924.48516 | F5: =F3*fin24m -> 272.5388
C6: Financiación a 120 meses | D6: =D3*fin120m -> 247.17721 | E6: =E3*fin120m -> 247.17721 | F6: =F3*fin120m -> 72.867994

Sheet exp0
B2: =empresa -> 0
B3: =nombre&" "&apellidos | C3: =fecha -> 45568
B4: =nif
B5: =telefono
B6: =direccion
B7: =cp&" "&localidad&" - "&provincia -> -
B8: =email
C13: ="r."&descuento*100 -> r.0 | E13: =num_mod -> 27 | G13: =p_gen -> 16.335 | H13: =cap_bat -> 0 | I13: =cálculos!P14 -> 25319.25 | J13: =cálculos!P33 -> 4691.9967 | K13: =cálculos!P55 -> #DIV/0!
E14: SIN BATERÍA | G14: CON BATERÍA | I14: SOLO BATERÍA | J14: SIN BATERÍA | K14: CON BATERÍA | L14: SOLO BATERÍA
D15: Sin IVA | E15: =ppto!G32 -> 16524.728 | G15: =ppto!H32 -> 16524.728 | I15: =ppto!I32 -> 4871.5
D16: Con IVA | E16: =ppto!G44 -> 19994.921 | G16: =ppto!H44 -> 19994.921 | I16: =ppto!I44 -> 5894.515 | J16: =E16 -> 19994.921 | K16: =G16 -> 19994.921 | L16: =I16 -> 5894.515
D17: Ayudas | E17: =-incentivo!C36 -> 0 | G17: =-incentivo!D36 -> 0 | I17: =-incentivo!E36 -> 0 | J17: =-E17 -> 0 | K17: =-G17 -> 0 | L17: =-I17 -> 0
D18: Total con Ayudas | E18: =E16+E17 -> 19994.921 | G18: =G16+G17 -> 19994.921 | I18: =I16+I17 -> 5894.515 | J18: =E18 -> 19994.921 | K18: =G18 -> 19994.921 | L18: =I18 -> 5894.515
C20: 10 años | E20: =finan!D6 -> 247.17721 | G20: =finan!E6 -> 247.17721 | I20: =finan!F6 -> 72.867994
C21: 2 años | E21: =finan!D5 -> 924.48516 | G21: =finan!E5 -> 924.48516 | I21: =finan!F5 -> 272.5388
C22: 1 año | E22: =finan!D4 -> 1778.9881 | G22: =finan!E4 -> 1778.9881 | I22: =finan!F4 -> 524.44679
E25: =incentivo!C37 -> 0 | G25: =incentivo!D37 -> 0 | I25: =incentivo!E37 -> 0 | J25: =E25 -> 0 | K25: =G25 -> 0 | L25: =I25 -> 0
E27: =programa -> Sinayuda | J27: =E27 -> Sinayuda | K27: =J27 -> Sinayuda | L27: =K27 -> Sinayuda
C29: =datos!F113 -> Excluídas | H29: Aceptación | J29: =adelanto -> 500 | K29: =adelanto -> 500 | L29: =adelanto -> 500
H30: Antes de Instalar | J30: =(ppto!G44/2)-adelanto -> 9497.4604 | K30: =(ppto!H44/2)-adelanto -> 9497.4604 | L30: =(ppto!I44/2)-adelanto -> 2447.2575
H31: Después de Instalar | J31: =ppto!G44-exp0!J29-exp0!J30 -> 9997.4604 | K31: =ppto!H44-exp0!K29-exp0!K30 -> 9997.4604 | L31: =ppto!I44-exp0!L29-exp0!L30 -> 2947.2575

Sheet exp2
B3: Producción Fovotolvaica | D3: =cálculos!P14 -> 25319.25 | K3: Producción Fovotolvaica | M3: =cálculos!P14 -> 25319.25
B5: Demanda Actual de la Red | D5: =cálculos!P7 -> 18171 | K5: Demanda Actual de la Red | M5: =cálculos!P7 -> 18171
B7: Demanda Futura de la Red | D7: =cálculos!P28 -> 9133.3315 | K7: Demanda Futura de la Red | M7: =cálculos!P50 -> #DIV/0!
B9: Autoconsumo | D9: =cálculos!P27 -> 9037.6685 | K9: Autoconsumo | M9: =cálculos!P49 -> #DIV/0!
B11: Excedente | D11: =cálculos!P29 -> 16281.582 | K11: Excedente | M11: =cálculos!P51 -> #DIV/0!
B13: Reducción de la Demanda de la Red: | D13: =cálculos!P23 -> 0.50490612
B70: Producción | C70: #FFD100
B71: Demanda Actual de la Red | C71: #FF3B3B
B72: Demanda Futura de la Red | C72: #FF33CC
B73: Autoconsumo | C73: #30F030
B74: Excedente | C74: #00B0F0

Sheet exp3
A1: Razón Social: | B1: =empresa -> 0 | C1: Dirección: | D1: =direccion
A2: NIF: | B2: =nif | C2: Código postal: | D2: =cp
A3: Nombre: | B3: =nombre | C3: Localidad: | D3: =localidad
A4: Apellidos: | B4: =apellidos | C4: Provincia: | D4: =provincia
A5: Email: | B5: =email | C5: CUPS: | D5: =cups
A6: Teléfono: | B6: =telefono | C6: Fecha: | D6: =fecha -> 45568

Sheet exp4
B1: ="Autoconsumo (Sin Baterías) de "&p_gen&" kW" -> Autoconsumo (Sin Baterías) de 16,335 kW | L1: Instalación Con baterías
B3: AÑO | C3: DEMANDA ACTUAL | D3: DEMANDA FUTURA | F3: PRODUCCIÓN FOTOVOLTAICA | G3: AUTOCONSUMO | J3: EXCEDENTE | L3: AÑO | M3: DEMANDA ACTUAL | N3: DEMANDA FUTURA | P3: PRODUCCIÓN FOTOVOLTAICA | Q3: AUTOCONSUMO | T3: EXCEDENTE
C4: (kWh/año) | D4: (kWh/año) | E4: Reducción de demanda (%) | F4: (kWh/año) | G4: Directo (kWh/año) | H4: Indirecto (kWh/año) | I4: Total (kWh/año) | J4: (kWh/año) | M4: (kWh/año) | N4: (kWh/año) | O4: (%) | P4: (kWh/año) | Q4: Directo (kWh/año) | R4: Indirecto (kWh/año) | S4: Total (kWh/año) | T4: (kWh/año)
B5: 0 | L5: 0
B6: 1 | C6: =t.con!O3 -> 18171 | D6: =cálculos!P28 -> 9133.3315 | E6: =cálculos!P23 -> 0.50490612 | F6: =cálculos!P14 -> 25319.25 | G6: =cálculos!P27 -> 9037.6685 | H6: 0 | I6: =G6+H6 -> 9037.6685 | J6: =cálculos!P29 -> 16281.582 | L6: 1 | M6: =cálculos!P7 -> 18171 | N6: =cálculos!P50 -> #DIV/0! | O6: =cálculos!P45 -> #DIV/0! | P6: =cálculos!P14 -> 25319.25 | Q6: =cálculos!P27 -> 9037.6685 | R6: =cálculos!P49-Q6 -> #DIV/0! | S6: =Q6+R6 -> #DIV/0! | T6: =P6-S6 -> #DIV/0!
B7: 2 | C7: =$C$6 -> 18171 | D7: =C7-I7 -> 9201.7467 | E7: =1-D7/C7 -> 0.49360263 | F7: =F6*coefper -> 25127.583 | G7: =G6*coefper -> 8969.2533 | H7: 0 | I7: =G7+H7 -> 8969.2533 | J7: =F7-I7 -> 16158.33 | L7: 2 | M7: =$M$6 -> 18171 | N7: =M7-S7 -> #DIV/0! | O7: =1-N7/M7 -> #DIV/0! | P7: =P6*coefper -> 25127.583 | Q7: =Q6*coefper -> 8969.2533 | R7: =R6-(1-coefper)*(R6/S6)*R6 -> #DIV/0! | S7: =Q7+R7 -> #DIV/0! | T7: =P7-S7 -> #DIV/0!
B8: 3 | C8: =$C$6 -> 18171 | D8: =C8-I8 -> 9269.6439 | E8: =1-D8/C8 -> 0.48986605 | F8: =F7*coefper -> 24937.367 | G8: =G7*coefper -> 8901.3561 | H8: 0 | I8: =G8+H8 -> 8901.3561 | J8: =F8-I8 -> 16036.011 | L8: 3 | M8: =$M$6 -> 18171 | N8: =M8-S8 -> #DIV/0! | O8: =1-N8/M8 -> #DIV/0! | P8: =P7*coefper -> 24937.367 | Q8: =Q7*coefper -> 8901.3561 | R8: =R7-(1-coefper)*(R7/S7)*R7 -> #DIV/0! | S8: =Q8+R8 -> #DIV/0! | T8: =P8-S8 -> #DIV/0!
B9: 4 | C9: =$C$6 -> 18171 | D9: =C9-I9 -> 9337.0272 | E9: =1-D9/C9 -> 0.48615777 | F9: =F8*coefper -> 24748.592 | G9: =G8*coefper -> 8833.9728 | H9: 0 | I9: =G9+H9 -> 8833.9728 | J9: =F9-I9 -> 15914.619 | L9: 4 | M9: =$M$6 -> 18171 | N9: =M9-S9 -> #DIV/0! | O9: =1-N9/M9 -> #DIV/0! | P9: =P8*coefper -> 24748.592 | Q9: =Q8*coefper -> 8833.9728 | R9: =R8-(1-coefper)*(R8/S8)*R8 -> #DIV/0! | S9: =Q9+R9 -> #DIV/0! | T9: =P9-S9 -> #DIV/0!
B10: 5 | C10: =$C$6 -> 18171 | D10: =C10-I10 -> 9403.9004 | E10: =1-D10/C10 -> 0.48247755 | F10: =F9*coefper -> 24561.245 | G10: =G9*coefper -> 8767.0996 | H10: 0 | I10: =G10+H10 -> 8767.0996 | J10: =F10-I10 -> 15794.145 | L10: 5 | M10: =$M$6 -> 18171 | N10: =M10-S10 -> #DIV/0! | O10: =1-N10/M10 -> #DIV/0! | P10: =P9*coefper -> 24561.245 | Q10: =Q9*coefper -> 8767.0996 | R10: =R9-(1-coefper)*(R9/S9)*R9 -> #DIV/0! | S10: =Q10+R10 -> #DIV/0! | T10: =P10-S10 -> #DIV/0!
B11: 6 | C11: =$C$6 -> 18171 | D11: =C11-I11 -> 9470.2673 | E11: =1-D11/C11 -> 0.4788252 | F11: =F10*coefper -> 24375.316 | G11: =G10*coefper -> 8700.7327 | H11: 0 | I11: =G11+H11 -> 8700.7327 | J11: =F11-I11 -> 15674.583 | L11: 6 | M11: =$M$6 -> 18171 | N11: =M11-S11 -> #DIV/0! | O11: =1-N11/M11 -> #DIV/0! | P11: =P10*coefper -> 24375.316 | Q11: =Q10*coefper -> 8700.7327 | R11: =R10-(1-coefper)*(R10/S10)*R10 -> #DIV/0! | S11: =Q11+R11 -> #DIV/0! | T11: =P11-S11 -> #DIV/0!
B12: 7 | C12: =$C$6 -> 18171 | D12: =C12-I12 -> 9536.1319 | E12: =1-D12/C12 -> 0.47520049 | F12: =F11*coefper -> 24190.795 | G12: =G11*coefper -> 8634.8681 | H12: 0 | I12: =G12+H12 -> 8634.8681 | J12: =F12-I12 -> 15555.927 | L12: 7 | M12: =$M$6 -> 18171 | N12: =M12-S12 -> #DIV/0! | O12: =1-N12/M12 -> #DIV/0! | P12: =P11*coefper -> 24190.795 | Q12: =Q11*coefper -> 8634.8681 | R12: =R11-(1-coefper)*(R11/S11)*R11 -> #DIV/0! | S12: =Q12+R12 -> #DIV/0! | T12: =P12-S12 -> #DIV/0!
B13: 8 | C13: =$C$6 -> 18171 | D13: =C13-I13 -> 9601.4978 | E13: =1-D13/C13 -> 0.47160322 | F13: =F12*coefper -> 24007.671 | G13: =G12*coefper -> 8569.5022 | H13: 0 | I13: =G13+H13 -> 8569.5022 | J13: =F13-I13 -> 15438.169 | L13: 8 | M13: =$M$6 -> 18171 | N13: =M13-S13 -> #DIV/0! | O13: =1-N13/M13 -> #DIV/0! | P13: =P12*coefper -> 24007.671 | Q13: =Q12*coefper -> 8569.5022 | R13: =R12-(1-coefper)*(R12/S12)*R12 -> #DIV/0! | S13: =Q13+R13 -> #DIV/0! | T13: =P13-S13 -> #DIV/0!
B14: 9 | C14: =$C$6 -> 18171 | D14: =C14-I14 -> 9666.369 | E14: =1-D14/C14 -> 0.46803319 | F14: =F13*coefper -> 23825.933 | G14: =G13*coefper -> 8504.631 | H14: 0 | I14: =G14+H14 -> 8504.631 | J14: =F14-I14 -> 15321.302 | L14: 9 | M14: =$M$6 -> 18171 | N14: =M14-S14 -> #DIV/0! | O14: =1-N14/M14 -> #DIV/0! | P14: =P13*coefper -> 23825.933 | Q14: =Q13*coefper -> 8504.631 | R14: =R13-(1-coefper)*(R13/S13)*R13 -> #DIV/0! | S14: =Q14+R14 -> #DIV/0! | T14: =P14-S14 -> #DIV/0!
B15: 10 | C15: =$C$6 -> 18171 | D15: =C15-I15 -> 9730.749 | E15: =1-D15/C15 -> 0.46449018 | F15: =F14*coefper -> 23645.57 | G15: =G14*coefper -> 8440.251 | H15: 0 | I15: =G15+H15 -> 8440.251 | J15: =F15-I15 -> 15205.319 | L15: 10 | M15: =$M$6 -> 18171 | N15: =M15-S15 -> #DIV/0! | O15: =1-N15/M15 -> #DIV/0! | P15: =P14*coefper -> 23645.57 | Q15: =Q14*coefper -> 8440.251 | R15: =R14-(1-coefper)*(R14/S14)*R14 -> #DIV/0! | S15: =Q15+R15 -> #DIV/0! | T15: =P15-S15 -> #DIV/0!
B16: 11 | C16: =$C$6 -> 18171 | D16: =C16-I16 -> 9794.6417 | E16: =1-D16/C16 -> 0.46097399 | F16: =F15*coefper -> 23466.573 | G16: =G15*coefper -> 8376.3583 | H16: 0 | I16: =G16+H16 -> 8376.3583 | J16: =F16-I16 -> 15090.215 | L16: 11 | M16: =$M$6 -> 18171 | N16: =M16-S16 -> #DIV/0! | O16: =1-N16/M16 -> #DIV/0! | P16: =P15*coefper -> 23466.573 | Q16: =Q15*coefper -> 8376.3583 | R16: =R15-(1-coefper)*(R15/S15)*R15 -> #DIV/0! | S16: =Q16+R16 -> #DIV/0! | T16: =P16-S16 -> #DIV/0!
B17: 12 | C17: =$C$6 -> 18171 | D17: =C17-I17 -> 9858.0507 | E17: =1-D17/C17 -> 0.45748441 | F17: =F16*coefper -> 23288.931 | G17: =G16*coefper -> 8312.9493 | H17: 0 | I17: =G17+H17 -> 8312.9493 | J17: =F17-I17 -> 14975.982 | L17: 12 | M17: =$M$6 -> 18171 | N17: =M17-S17 -> #DIV/0! | O17: =1-N17/M17 -> #DIV/0! | P17: =P16*coefper -> 23288.931 | Q17: =Q16*coefper -> 8312.9493 | R17: =R16-(1-coefper)*(R16/S16)*R16 -> #DIV/0! | S17: =Q17+R17 -> #DIV/0! | T17: =P17-S17 -> #DIV/0!
B18: 13 | C18: =$C$6 -> 18171 | D18: =C18-I18 -> 9920.9798 | E18: =1-D18/C18 -> 0.45402126 | F18: =F17*coefper -> 23112.634 | G18: =G17*coefper -> 8250.0202 | H18: 0 | I18: =G18+H18 -> 8250.0202 | J18: =F18-I18 -> 14862.614 | L18: 13 | M18: =$M$6 -> 18171 | N18: =M18-S18 -> #DIV/0! | O18: =1-N18/M18 -> #DIV/0! | P18: =P17*coefper -> 23112.634 | Q18: =Q17*coefper -> 8250.0202 | R18: =R17-(1-coefper)*(R17/S17)*R17 -> #DIV/0! | S18: =Q18+R18 -> #DIV/0! | T18: =P18-S18 -> #DIV/0!
